<?xml version="1.0"?>
<robot name="diffbot">
  <!-- Base chassis -->
  <link name="base_link">
    <inertial>
      <mass value="5.0"/>
      <origin xyz="0 0 0.05" rpy="0 0 0"/>
      <inertia ixx="0.05" ixy="0" ixz="0" iyy="0.05" iyz="0" izz="0.08"/>
    </inertial>
    <visual>
      <origin xyz="0 0 0.05" rpy="0 0 0"/>
      <geometry><box size="0.35 0.25 0.10"/></geometry>
      <material name="blue">
        <color rgba="0.1 0.3 0.8 1.0"/>
      </material>
    </visual>
    <collision>
      <origin xyz="0 0 0.05" rpy="0 0 0"/>
      <geometry><box size="0.35 0.25 0.10"/></geometry>
    </collision>
  </link>

  <!-- Left wheel -->
  <link name="left_wheel">
    <inertial>
      <mass value="0.3"/>
      <origin xyz="0 0 0" rpy="0 0 0"/>
      <inertia ixx="0.0005" ixy="0" ixz="0" iyy="0.0005" iyz="0" izz="0.001"/>
    </inertial>
    <visual>
      <geometry><cylinder length="0.025" radius="0.04"/></geometry>
      <material name="dark">
        <color rgba="0.2 0.2 0.2 1.0"/>
      </material>
    </visual>
    <collision>
      <geometry><cylinder length="0.025" radius="0.04"/></geometry>
    </collision>
  </link>

  <joint name="left_wheel_joint" type="continuous">
    <parent link="base_link"/>
    <child link="left_wheel"/>
    <origin xyz="0.0 0.14 0.0" rpy="-1.5708 0 0"/>
    <axis xyz="0 0 1"/>
    <dynamics damping="0.01" friction="0.05"/>
  </joint>

  <!-- Right wheel -->
  <link name="right_wheel">
    <inertial>
      <mass value="0.3"/>
      <origin xyz="0 0 0" rpy="0 0 0"/>
      <inertia ixx="0.0005" ixy="0" ixz="0" iyy="0.0005" iyz="0" izz="0.001"/>
    </inertial>
    <visual>
      <geometry><cylinder length="0.025" radius="0.04"/></geometry>
      <material name="dark">
        <color rgba="0.2 0.2 0.2 1.0"/>
      </material>
    </visual>
    <collision>
      <geometry><cylinder length="0.025" radius="0.04"/></geometry>
    </collision>
  </link>

  <joint name="right_wheel_joint" type="continuous">
    <parent link="base_link"/>
    <child link="right_wheel"/>
    <origin xyz="0.0 -0.14 0.0" rpy="-1.5708 0 0"/>
    <axis xyz="0 0 1"/>
    <dynamics damping="0.01" friction="0.05"/>
  </joint>

  <!-- Front caster (passive) -->
  <link name="caster_wheel">
    <inertial>
      <mass value="0.1"/>
      <origin xyz="0 0 0" rpy="0 0 0"/>
      <inertia ixx="0.0001" ixy="0" ixz="0" iyy="0.0001" iyz="0" izz="0.0001"/>
    </inertial>
    <visual>
      <geometry><sphere radius="0.02"/></geometry>
      <material name="dark"/>
    </visual>
    <collision>
      <geometry><sphere radius="0.02"/></geometry>
    </collision>
  </link>

  <joint name="caster_joint" type="fixed">
    <parent link="base_link"/>
    <child link="caster_wheel"/>
    <origin xyz="0.15 0 -0.02" rpy="0 0 0"/>
  </joint>
</robot>
